2020-01-11 15:54:09,986 ERROR: Exception on /users/login [POST]
Traceback (most recent call last):
  File "C:\Program Files\Python37\lib\site-packages\flask\app.py", line 2446, in wsgi_app
    response = self.full_dispatch_request()
  File "C:\Program Files\Python37\lib\site-packages\flask\app.py", line 1951, in full_dispatch_request
    rv = self.handle_user_exception(e)
  File "C:\Program Files\Python37\lib\site-packages\flask\app.py", line 1820, in handle_user_exception
    reraise(exc_type, exc_value, tb)
  File "C:\Program Files\Python37\lib\site-packages\flask\_compat.py", line 39, in reraise
    raise value
  File "C:\Program Files\Python37\lib\site-packages\flask\app.py", line 1949, in full_dispatch_request
    rv = self.dispatch_request()
  File "C:\Program Files\Python37\lib\site-packages\flask\app.py", line 1935, in dispatch_request
    return self.view_functions[rule.endpoint](**req.view_args)
  File "D:\dev\eme\bundle\eme\auth\utils.py", line 18, in decorated_view
    return func(*args, **kwargs)
  File "D:\dev\eme\bundle\webapp\controllers\UsersController.py", line 53, in post_login
    auth.set_user(user, remember=remember)
  File "D:\dev\eme\bundle\webapp\services\auth.py", line 89, in set_user
    login_user(UserAuth(user), remember=remember)
TypeError: __init__() takes 1 positional argument but 2 were given
2020-01-11 15:55:37,639 ERROR: Exception on /users/login [POST]
Traceback (most recent call last):
  File "C:\Program Files\Python37\lib\site-packages\flask\app.py", line 2446, in wsgi_app
    response = self.full_dispatch_request()
  File "C:\Program Files\Python37\lib\site-packages\flask\app.py", line 1951, in full_dispatch_request
    rv = self.handle_user_exception(e)
  File "C:\Program Files\Python37\lib\site-packages\flask\app.py", line 1820, in handle_user_exception
    reraise(exc_type, exc_value, tb)
  File "C:\Program Files\Python37\lib\site-packages\flask\_compat.py", line 39, in reraise
    raise value
  File "C:\Program Files\Python37\lib\site-packages\flask\app.py", line 1949, in full_dispatch_request
    rv = self.dispatch_request()
  File "C:\Program Files\Python37\lib\site-packages\flask\app.py", line 1935, in dispatch_request
    return self.view_functions[rule.endpoint](**req.view_args)
  File "D:\dev\eme\bundle\eme\auth\utils.py", line 18, in decorated_view
    return func(*args, **kwargs)
  File "D:\dev\eme\bundle\webapp\controllers\UsersController.py", line 53, in post_login
    auth.set_user(user, remember=remember)
  File "D:\dev\eme\bundle\webapp\services\auth.py", line 57, in set_user
    login_user(UserAuth(user), remember=remember)
NameError: name 'UserAuth' is not defined
2020-01-11 15:56:13,587 ERROR: Exception on / [GET]
Traceback (most recent call last):
  File "C:\Program Files\Python37\lib\site-packages\sqlalchemy\engine\base.py", line 1173, in _execute_context
    context = constructor(dialect, self, conn, *args)
  File "C:\Program Files\Python37\lib\site-packages\sqlalchemy\engine\default.py", line 799, in _init_compiled
    param.append(processors[key](compiled_params[key]))
  File "C:\Program Files\Python37\lib\site-packages\sqlalchemy\sql\type_api.py", line 1220, in process
    return process_param(value, dialect)
  File "D:\dev\eme\bundle\eme\data_access.py", line 30, in process_bind_param
    return "%.32x" % uuid.UUID(value).int
  File "C:\Program Files\Python37\lib\uuid.py", line 160, in __init__
    raise ValueError('badly formed hexadecimal UUID string')
ValueError: badly formed hexadecimal UUID string

The above exception was the direct cause of the following exception:

Traceback (most recent call last):
  File "C:\Program Files\Python37\lib\site-packages\flask\app.py", line 2446, in wsgi_app
    response = self.full_dispatch_request()
  File "C:\Program Files\Python37\lib\site-packages\flask\app.py", line 1951, in full_dispatch_request
    rv = self.handle_user_exception(e)
  File "C:\Program Files\Python37\lib\site-packages\flask\app.py", line 1820, in handle_user_exception
    reraise(exc_type, exc_value, tb)
  File "C:\Program Files\Python37\lib\site-packages\flask\_compat.py", line 39, in reraise
    raise value
  File "C:\Program Files\Python37\lib\site-packages\flask\app.py", line 1949, in full_dispatch_request
    rv = self.dispatch_request()
  File "C:\Program Files\Python37\lib\site-packages\flask\app.py", line 1935, in dispatch_request
    return self.view_functions[rule.endpoint](**req.view_args)
  File "D:\dev\eme\bundle\webapp\controllers\HomeController.py", line 9, in welcome
    return render_template('/home/index.html')
  File "C:\Program Files\Python37\lib\site-packages\flask\templating.py", line 136, in render_template
    ctx.app.update_template_context(context)
  File "C:\Program Files\Python37\lib\site-packages\flask\app.py", line 838, in update_template_context
    context.update(func())
  File "C:\Program Files\Python37\lib\site-packages\flask_login\utils.py", line 368, in _user_context_processor
    return dict(current_user=_get_user())
  File "C:\Program Files\Python37\lib\site-packages\flask_login\utils.py", line 335, in _get_user
    current_app.login_manager._load_user()
  File "C:\Program Files\Python37\lib\site-packages\flask_login\login_manager.py", line 359, in _load_user
    return self.reload_user()
  File "C:\Program Files\Python37\lib\site-packages\flask_login\login_manager.py", line 321, in reload_user
    user = self.user_callback(user_id)
  File "D:\dev\eme\bundle\webapp\services\auth.py", line 36, in load_user
    return user_repo.get(uid)
  File "D:\dev\eme\bundle\eme\data_access.py", line 103, in get
    return self.session.query(self.T).get(eid)
  File "C:\Program Files\Python37\lib\site-packages\sqlalchemy\orm\query.py", line 982, in get
    return self._get_impl(ident, loading.load_on_pk_identity)
  File "C:\Program Files\Python37\lib\site-packages\sqlalchemy\orm\query.py", line 1094, in _get_impl
    return db_load_fn(self, primary_key_identity)
  File "C:\Program Files\Python37\lib\site-packages\sqlalchemy\orm\loading.py", line 284, in load_on_pk_identity
    return q.one()
  File "C:\Program Files\Python37\lib\site-packages\sqlalchemy\orm\query.py", line 3325, in one
    ret = self.one_or_none()
  File "C:\Program Files\Python37\lib\site-packages\sqlalchemy\orm\query.py", line 3294, in one_or_none
    ret = list(self)
  File "C:\Program Files\Python37\lib\site-packages\sqlalchemy\orm\query.py", line 3367, in __iter__
    return self._execute_and_instances(context)
  File "C:\Program Files\Python37\lib\site-packages\sqlalchemy\orm\query.py", line 3392, in _execute_and_instances
    result = conn.execute(querycontext.statement, self._params)
  File "C:\Program Files\Python37\lib\site-packages\sqlalchemy\engine\base.py", line 982, in execute
    return meth(self, multiparams, params)
  File "C:\Program Files\Python37\lib\site-packages\sqlalchemy\sql\elements.py", line 287, in _execute_on_connection
    return connection._execute_clauseelement(self, multiparams, params)
  File "C:\Program Files\Python37\lib\site-packages\sqlalchemy\engine\base.py", line 1101, in _execute_clauseelement
    distilled_params,
  File "C:\Program Files\Python37\lib\site-packages\sqlalchemy\engine\base.py", line 1176, in _execute_context
    e, util.text_type(statement), parameters, None, None
  File "C:\Program Files\Python37\lib\site-packages\sqlalchemy\engine\base.py", line 1476, in _handle_dbapi_exception
    util.raise_from_cause(sqlalchemy_exception, exc_info)
  File "C:\Program Files\Python37\lib\site-packages\sqlalchemy\util\compat.py", line 398, in raise_from_cause
    reraise(type(exception), exception, tb=exc_tb, cause=cause)
  File "C:\Program Files\Python37\lib\site-packages\sqlalchemy\util\compat.py", line 152, in reraise
    raise value.with_traceback(tb)
  File "C:\Program Files\Python37\lib\site-packages\sqlalchemy\engine\base.py", line 1173, in _execute_context
    context = constructor(dialect, self, conn, *args)
  File "C:\Program Files\Python37\lib\site-packages\sqlalchemy\engine\default.py", line 799, in _init_compiled
    param.append(processors[key](compiled_params[key]))
  File "C:\Program Files\Python37\lib\site-packages\sqlalchemy\sql\type_api.py", line 1220, in process
    return process_param(value, dialect)
  File "D:\dev\eme\bundle\eme\data_access.py", line 30, in process_bind_param
    return "%.32x" % uuid.UUID(value).int
  File "C:\Program Files\Python37\lib\uuid.py", line 160, in __init__
    raise ValueError('badly formed hexadecimal UUID string')
sqlalchemy.exc.StatementError: (builtins.ValueError) badly formed hexadecimal UUID string
[SQL: SELECT users.uid AS users_uid, users.created_at AS users_created_at, users.last_time AS users_last_time, users.username AS users_username, users.email AS users_email, users.salt AS users_salt, users.token AS users_token, users.password AS users_password, users.admin AS users_admin 
FROM users 
WHERE users.uid = ?]
[parameters: [{'%(2921781916424 param)s': 'kurva_anyukad.'}]]
2020-01-11 15:57:07,366 ERROR: Exception on / [GET]
Traceback (most recent call last):
  File "C:\Program Files\Python37\lib\site-packages\sqlalchemy\engine\base.py", line 1173, in _execute_context
    context = constructor(dialect, self, conn, *args)
  File "C:\Program Files\Python37\lib\site-packages\sqlalchemy\engine\default.py", line 799, in _init_compiled
    param.append(processors[key](compiled_params[key]))
  File "C:\Program Files\Python37\lib\site-packages\sqlalchemy\sql\type_api.py", line 1220, in process
    return process_param(value, dialect)
  File "D:\dev\eme\bundle\eme\data_access.py", line 30, in process_bind_param
    return "%.32x" % uuid.UUID(value).int
  File "C:\Program Files\Python37\lib\uuid.py", line 160, in __init__
    raise ValueError('badly formed hexadecimal UUID string')
ValueError: badly formed hexadecimal UUID string

The above exception was the direct cause of the following exception:

Traceback (most recent call last):
  File "C:\Program Files\Python37\lib\site-packages\flask\app.py", line 2446, in wsgi_app
    response = self.full_dispatch_request()
  File "C:\Program Files\Python37\lib\site-packages\flask\app.py", line 1951, in full_dispatch_request
    rv = self.handle_user_exception(e)
  File "C:\Program Files\Python37\lib\site-packages\flask\app.py", line 1820, in handle_user_exception
    reraise(exc_type, exc_value, tb)
  File "C:\Program Files\Python37\lib\site-packages\flask\_compat.py", line 39, in reraise
    raise value
  File "C:\Program Files\Python37\lib\site-packages\flask\app.py", line 1949, in full_dispatch_request
    rv = self.dispatch_request()
  File "C:\Program Files\Python37\lib\site-packages\flask\app.py", line 1935, in dispatch_request
    return self.view_functions[rule.endpoint](**req.view_args)
  File "D:\dev\eme\bundle\webapp\controllers\HomeController.py", line 9, in welcome
    return render_template('/home/index.html')
  File "C:\Program Files\Python37\lib\site-packages\flask\templating.py", line 136, in render_template
    ctx.app.update_template_context(context)
  File "C:\Program Files\Python37\lib\site-packages\flask\app.py", line 838, in update_template_context
    context.update(func())
  File "C:\Program Files\Python37\lib\site-packages\flask_login\utils.py", line 368, in _user_context_processor
    return dict(current_user=_get_user())
  File "C:\Program Files\Python37\lib\site-packages\flask_login\utils.py", line 335, in _get_user
    current_app.login_manager._load_user()
  File "C:\Program Files\Python37\lib\site-packages\flask_login\login_manager.py", line 359, in _load_user
    return self.reload_user()
  File "C:\Program Files\Python37\lib\site-packages\flask_login\login_manager.py", line 321, in reload_user
    user = self.user_callback(user_id)
  File "D:\dev\eme\bundle\webapp\services\auth.py", line 36, in load_user
    return user_repo.get(uid)
  File "D:\dev\eme\bundle\eme\data_access.py", line 103, in get
    return self.session.query(self.T).get(eid)
  File "C:\Program Files\Python37\lib\site-packages\sqlalchemy\orm\query.py", line 982, in get
    return self._get_impl(ident, loading.load_on_pk_identity)
  File "C:\Program Files\Python37\lib\site-packages\sqlalchemy\orm\query.py", line 1094, in _get_impl
    return db_load_fn(self, primary_key_identity)
  File "C:\Program Files\Python37\lib\site-packages\sqlalchemy\orm\loading.py", line 284, in load_on_pk_identity
    return q.one()
  File "C:\Program Files\Python37\lib\site-packages\sqlalchemy\orm\query.py", line 3325, in one
    ret = self.one_or_none()
  File "C:\Program Files\Python37\lib\site-packages\sqlalchemy\orm\query.py", line 3294, in one_or_none
    ret = list(self)
  File "C:\Program Files\Python37\lib\site-packages\sqlalchemy\orm\query.py", line 3367, in __iter__
    return self._execute_and_instances(context)
  File "C:\Program Files\Python37\lib\site-packages\sqlalchemy\orm\query.py", line 3392, in _execute_and_instances
    result = conn.execute(querycontext.statement, self._params)
  File "C:\Program Files\Python37\lib\site-packages\sqlalchemy\engine\base.py", line 982, in execute
    return meth(self, multiparams, params)
  File "C:\Program Files\Python37\lib\site-packages\sqlalchemy\sql\elements.py", line 287, in _execute_on_connection
    return connection._execute_clauseelement(self, multiparams, params)
  File "C:\Program Files\Python37\lib\site-packages\sqlalchemy\engine\base.py", line 1101, in _execute_clauseelement
    distilled_params,
  File "C:\Program Files\Python37\lib\site-packages\sqlalchemy\engine\base.py", line 1176, in _execute_context
    e, util.text_type(statement), parameters, None, None
  File "C:\Program Files\Python37\lib\site-packages\sqlalchemy\engine\base.py", line 1476, in _handle_dbapi_exception
    util.raise_from_cause(sqlalchemy_exception, exc_info)
  File "C:\Program Files\Python37\lib\site-packages\sqlalchemy\util\compat.py", line 398, in raise_from_cause
    reraise(type(exception), exception, tb=exc_tb, cause=cause)
  File "C:\Program Files\Python37\lib\site-packages\sqlalchemy\util\compat.py", line 152, in reraise
    raise value.with_traceback(tb)
  File "C:\Program Files\Python37\lib\site-packages\sqlalchemy\engine\base.py", line 1173, in _execute_context
    context = constructor(dialect, self, conn, *args)
  File "C:\Program Files\Python37\lib\site-packages\sqlalchemy\engine\default.py", line 799, in _init_compiled
    param.append(processors[key](compiled_params[key]))
  File "C:\Program Files\Python37\lib\site-packages\sqlalchemy\sql\type_api.py", line 1220, in process
    return process_param(value, dialect)
  File "D:\dev\eme\bundle\eme\data_access.py", line 30, in process_bind_param
    return "%.32x" % uuid.UUID(value).int
  File "C:\Program Files\Python37\lib\uuid.py", line 160, in __init__
    raise ValueError('badly formed hexadecimal UUID string')
sqlalchemy.exc.StatementError: (builtins.ValueError) badly formed hexadecimal UUID string
[SQL: SELECT users.uid AS users_uid, users.created_at AS users_created_at, users.last_time AS users_last_time, users.username AS users_username, users.email AS users_email, users.salt AS users_salt, users.token AS users_token, users.password AS users_password, users.admin AS users_admin 
FROM users 
WHERE users.uid = ?]
[parameters: [{'%(2174446529864 param)s': 'kurva_anyukad.'}]]
2020-01-11 16:00:38,692 ERROR: Exception on / [GET]
Traceback (most recent call last):
  File "C:\Program Files\Python37\lib\site-packages\flask\app.py", line 2446, in wsgi_app
    response = self.full_dispatch_request()
  File "C:\Program Files\Python37\lib\site-packages\flask\app.py", line 1951, in full_dispatch_request
    rv = self.handle_user_exception(e)
  File "C:\Program Files\Python37\lib\site-packages\flask\app.py", line 1820, in handle_user_exception
    reraise(exc_type, exc_value, tb)
  File "C:\Program Files\Python37\lib\site-packages\flask\_compat.py", line 39, in reraise
    raise value
  File "C:\Program Files\Python37\lib\site-packages\flask\app.py", line 1949, in full_dispatch_request
    rv = self.dispatch_request()
  File "C:\Program Files\Python37\lib\site-packages\flask\app.py", line 1935, in dispatch_request
    return self.view_functions[rule.endpoint](**req.view_args)
  File "D:\dev\eme\bundle\webapp\controllers\HomeController.py", line 10, in welcome
    return render_template('/home/index.html')
  File "C:\Program Files\Python37\lib\site-packages\flask\templating.py", line 140, in render_template
    ctx.app,
  File "C:\Program Files\Python37\lib\site-packages\flask\templating.py", line 120, in _render
    rv = template.render(context)
  File "C:\Program Files\Python37\lib\site-packages\jinja2\asyncsupport.py", line 76, in render
    return original_render(self, *args, **kwargs)
  File "C:\Program Files\Python37\lib\site-packages\jinja2\environment.py", line 1008, in render
    return self.environment.handle_exception(exc_info, True)
  File "C:\Program Files\Python37\lib\site-packages\jinja2\environment.py", line 780, in handle_exception
    reraise(exc_type, exc_value, tb)
  File "C:\Program Files\Python37\lib\site-packages\jinja2\_compat.py", line 37, in reraise
    raise value.with_traceback(tb)
  File "D:\dev\eme\bundle\webapp\templates\layout.html", line 85, in template
    {% block content %}{% endblock %}
  File "C:\Program Files\Python37\lib\site-packages\jinja2\environment.py", line 1005, in render
    return concat(self.root_render_func(self.new_context(vars)))
  File "D:\dev\eme\bundle\webapp\templates\home\index.html", line 12, in root
    <p>Check out the examples:</p>
  File "C:\Program Files\Python37\lib\site-packages\jinja2\environment.py", line 830, in get_template
    return self._load_template(name, self.make_globals(globals))
  File "C:\Program Files\Python37\lib\site-packages\jinja2\environment.py", line 804, in _load_template
    template = self.loader.load(self, name, globals)
  File "C:\Program Files\Python37\lib\site-packages\jinja2\loaders.py", line 125, in load
    code = environment.compile(source, name, filename)
  File "C:\Program Files\Python37\lib\site-packages\jinja2\environment.py", line 591, in compile
    self.handle_exception(exc_info, source_hint=source_hint)
  File "C:\Program Files\Python37\lib\site-packages\jinja2\environment.py", line 780, in handle_exception
    reraise(exc_type, exc_value, tb)
  File "C:\Program Files\Python37\lib\site-packages\jinja2\_compat.py", line 37, in reraise
    raise value.with_traceback(tb)
  File "D:\dev\eme\bundle\webapp\templates\layout.html", line 85, in template
    {% block content %}{% endblock %}
  File "C:\Program Files\Python37\lib\site-packages\jinja2\environment.py", line 497, in _parse
    return Parser(self, source, name, encode_filename(filename)).parse()
  File "C:\Program Files\Python37\lib\site-packages\jinja2\parser.py", line 901, in parse
    result = nodes.Template(self.subparse(), lineno=1)
  File "C:\Program Files\Python37\lib\site-packages\jinja2\parser.py", line 883, in subparse
    rv = self.parse_statement()
  File "C:\Program Files\Python37\lib\site-packages\jinja2\parser.py", line 130, in parse_statement
    return getattr(self, 'parse_' + self.stream.current.value)()
  File "C:\Program Files\Python37\lib\site-packages\jinja2\parser.py", line 223, in parse_if
    drop_needle=True)
  File "C:\Program Files\Python37\lib\site-packages\jinja2\parser.py", line 170, in parse_statements
    self.fail_eof(end_tokens)
  File "C:\Program Files\Python37\lib\site-packages\jinja2\parser.py", line 104, in fail_eof
    return self._fail_ut_eof(None, stack, lineno)
  File "C:\Program Files\Python37\lib\site-packages\jinja2\parser.py", line 90, in _fail_ut_eof
    self.fail(' '.join(message), lineno)
  File "C:\Program Files\Python37\lib\site-packages\jinja2\parser.py", line 59, in fail
    raise exc(msg, lineno, self.name, self.filename)
jinja2.exceptions.TemplateSyntaxError: Unexpected end of template. Jinja was looking for the following tags: 'endif'. The innermost block that needs to be closed is 'if'.
